<mujoco model="T1">
    <compiler angle="radian" meshdir="meshes/" />
    <size njmax="500" nconmax="100" />
    <asset>
        <texture type="skybox" builtin="gradient" rgb1="0.3 0.5 0.7" rgb2="0 0 0" width="512" height="512"/>
        <texture name="texplane" type="2d" builtin="checker" rgb1=".2 .3 .4" rgb2=".1 0.15 0.2" width="512" height="512" mark="cross" markrgb=".8 .8 .8"/>
        <material name="matplane" reflectance="0.3" texture="texplane" texrepeat="1 1" texuniform="true"/>
        <mesh name="Trunk" file="Trunk.STL" />
        <mesh name="H1" file="H1.STL" />
        <mesh name="H2" file="H2.STL" />
        <mesh name="AL1" file="AL1.STL" />
        <mesh name="AL2" file="AL2.STL" />
        <mesh name="AL3" file="AL3.STL" />
        <mesh name="left_hand_link" file="left_hand_link.STL" />
        <mesh name="AR1" file="AR1.STL" />
        <mesh name="AR2" file="AR2.STL" />
        <mesh name="AR3" file="AR3.STL" />
        <mesh name="right_hand_link" file="right_hand_link.STL" />
        <mesh name="Waist" file="Waist.STL" />
        <mesh name="Hip_Pitch_Left" file="Hip_Pitch_Left.STL" />
        <mesh name="Hip_Roll_Left" file="Hip_Roll_Left.STL" />
        <mesh name="Hip_Yaw_Left" file="Hip_Yaw_Left.STL" />
        <mesh name="Shank_Left" file="Shank_Left.STL" />
        <mesh name="Ankle_Cross_Left" file="Ankle_Cross_Left.STL" />
        <mesh name="left_foot_link" file="left_foot_link.STL" />
        <mesh name="Hip_Pitch_Right" file="Hip_Pitch_Right.STL" />
        <mesh name="Hip_Roll_Right" file="Hip_Roll_Right.STL" />
        <mesh name="Hip_Yaw_Right" file="Hip_Yaw_Right.STL" />
        <mesh name="Shank_Right" file="Shank_Right.STL" />
        <mesh name="Ankle_Cross_Right" file="Ankle_Cross_Right.STL" />
        <mesh name="right_foot_link" file="right_foot_link.STL" />
    </asset>
    <worldbody>
        <light directional="true" diffuse=".4 .4 .4" specular="0.1 0.1 0.1" pos="0 0 5.0" dir="0 0 -1" castshadow="false" />
        <light directional="true" diffuse=".6 .6 .6" specular="0.2 0.2 0.2" pos="0 0 4" dir="0 0 -1" />
        <geom name="ground" type="plane" pos="0 0 0" size="0 0 1" material="matplane" condim="1"/>
        <body name="Trunk" pos="0 0 0.7">
            <inertial pos="0.0561239 1.22834e-05 0.126592" quat="0.999927 -0.000455025 0.012016 -0.000950608" mass="12.7749" diaginertia="0.161056 0.14631 0.0576017" />
            <site name='imu' size='0.01' pos='0.0 0.0 0.0' />
            <joint type="free" />
            <geom type="mesh" contype="0" conaffinity="0" group="1" rgba="0.76 0.76 0.76 0.2" mesh="Trunk" />
            <geom size="0.075 0.1 0.15" pos="0.06 0 0.12" type="box" rgba="0.76 0.76 0.76 0.2" />
            <geom pos="0.0625 0 0.243" type="mesh" contype="0" conaffinity="0" group="1" rgba="0.4 0.4 0.4 0.3" mesh="H1" />
            <geom pos="0.0625 0 0.30485" type="mesh" contype="0" conaffinity="0" group="1" rgba="0.4 0.4 0.4 0.3" mesh="H2" />
            <geom size="0.08" pos="0.0725 0 0.41485" rgba="0.4 0.4 0.4 0.3" />
            <body name="AL1" pos="0.0575 0.1063 0.219" quat="1 0 0.000440565 0">
                <inertial pos="-0.000677 0.044974 0" quat="0.50423 0.495734 -0.50423 0.495734" mass="0.53" diaginertia="0.001367 0.00129329 0.000292711" />
                <joint name="Left_Shoulder_Pitch" pos="0 0 0" axis="0 1 0" limited="true" range="-3.31 1.22" />
                <geom type="mesh" contype="0" conaffinity="0" group="1" rgba="0.76 0.76 0.76 0.2" mesh="AL1" />
                <geom type="mesh" rgba="0.76 0.76 0.76 0.2" mesh="AL1" />
                <body name="AL2" pos="0 0.047 0">
                    <inertial pos="0.003862 0.037976 0" quat="0.487991 0.511727 -0.487991 0.511727" mass="0.16" diaginertia="0.000401 0.00034538 0.00017662" />
                    <joint name="Left_Shoulder_Roll" pos="0 0 0" axis="1 0 0" limited="true" range="-1.74 1.57" />
                    <geom type="mesh" contype="0" conaffinity="0" group="1" rgba="0.4 0.4 0.4 0.3" mesh="AL2" />
                    <geom type="mesh" rgba="0.4 0.4 0.4 0.3" mesh="AL2" />
                    <body name="AL3" pos="0.00025 0.0605 0">
                        <inertial pos="0 0.085353 -9.9e-05" quat="0.70641 0.707803 0 0" mass="1.02" diaginertia="0.012869 0.012798 0.000620953" />
                        <joint name="Left_Elbow_Pitch" pos="0 0 0" axis="0 1 0" limited="true" range="-2.27 2.27" />
                        <geom type="mesh" contype="0" conaffinity="0" group="1" rgba="0.4 0.4 0.4 0.3" mesh="AL3" />
                        <geom type="mesh" rgba="0.4 0.4 0.4 0.3" mesh="AL3" />
                        <body name="left_hand_link" pos="0 0.1471 0">
                            <inertial pos="-0.000108 0.109573 0.000591" quat="0.707866 0.706347 -5.22939e-05 -0.000214913" mass="0.327214" diaginertia="0.008159 0.00813104 0.000214962" />
                            <joint name="Left_Elbow_Yaw" pos="0 0 0" axis="0 0 1" limited="true" range="-2.44 0" />
                            <geom type="mesh" contype="0" conaffinity="0" group="1" rgba="0.4 0.4 0.4 0.3" mesh="left_hand_link" />
                            <geom type="mesh" rgba="0.4 0.4 0.4 0.3" mesh="left_hand_link" />
                        </body>
                    </body>
                </body>
            </body>
            <body name="AR1" pos="0.0575 -0.1063 0.219" quat="1 0 0.000440565 0">
                <inertial pos="-0.000677 -0.044974 0" quat="0.50423 0.495734 -0.50423 0.495734" mass="0.53" diaginertia="0.001367 0.00129329 0.000292711" />
                <joint name="Right_Shoulder_Pitch" pos="0 0 0" axis="0 1 0" limited="true" range="-3.31 1.22" />
                <geom type="mesh" contype="0" conaffinity="0" group="1" rgba="0.76 0.76 0.76 0.2" mesh="AR1" />
                <geom type="mesh" rgba="0.76 0.76 0.76 0.2" mesh="AR1" />
                <body name="AR2" pos="0 -0.047 0">
                    <inertial pos="0.003862 -0.037976 0" quat="0.511727 0.487991 -0.511727 0.487991" mass="0.16" diaginertia="0.000401 0.00034538 0.00017662" />
                    <joint name="Right_Shoulder_Roll" pos="0 0 0" axis="1 0 0" limited="true" range="-1.57 1.74" />
                    <geom type="mesh" contype="0" conaffinity="0" group="1" rgba="0.4 0.4 0.4 0.3" mesh="AR2" />
                    <geom type="mesh" rgba="0.4 0.4 0.4 0.3" mesh="AR2" />
                    <body name="AR3" pos="0.00025 -0.0605 0">
                        <inertial pos="0 -0.085353 -9.9e-05" quat="0.707803 0.70641 0 0" mass="1.02" diaginertia="0.012869 0.012798 0.000620953" />
                        <joint name="Right_Elbow_Pitch" pos="0 0 0" axis="0 1 0" limited="true" range="-2.27 2.27" />
                        <geom type="mesh" contype="0" conaffinity="0" group="1" rgba="0.4 0.4 0.4 0.3" mesh="AR3" />
                        <geom type="mesh" rgba="0.4 0.4 0.4 0.3" mesh="AR3" />
                        <body name="right_hand_link" pos="0 -0.1471 0">
                            <inertial pos="-0.000108 -0.109573 0.000591" quat="0.706347 0.707866 0.000214913 5.22939e-05" mass="0.327214" diaginertia="0.008159 0.00813104 0.000214962" />
                            <joint name="Right_Elbow_Yaw" pos="0 0 0" axis="0 0 1" limited="true" range="0 2.44" />
                            <geom type="mesh" contype="0" conaffinity="0" group="1" rgba="0.4 0.4 0.4 0.3" mesh="right_hand_link" />
                            <geom type="mesh" rgba="0.4 0.4 0.4 0.3" mesh="right_hand_link" />
                        </body>
                    </body>
                </body>
            </body>
            <body name="Waist" pos="0.0625 0 -0.1155">
                <inertial pos="0.002284 3e-06 0.007301" quat="0.983649 0.000360386 -0.180076 0.00269791" mass="2.581" diaginertia="0.00536742 0.005299 0.00474258" />
                <joint name="Waist" pos="0 0 0" axis="0 0 1" limited="true" range="-1.57 1.57" />
                <geom type="mesh" contype="0" conaffinity="0" group="1" rgba="0.4 0.4 0.4 0.3" mesh="Waist" />
                <body name="Hip_Pitch_Left" pos="0 0.106 0">
                    <inertial pos="0.000534 -0.007296 -0.018083" quat="0.975141 0.2211 0.0145808 0.0017406" mass="1.021" diaginertia="0.00180547 0.00145926 0.00125327" />
                    <joint name="Left_Hip_Pitch" pos="0 0 0" axis="0 1 0" limited="true" range="-1.8 1.57" />
                    <geom type="mesh" contype="0" conaffinity="0" group="1" rgba="0.76 0.76 0.76 0.2" mesh="Hip_Pitch_Left" />
                    <body name="Hip_Roll_Left" pos="0 0 -0.02">
                        <inertial pos="0.001101 2.4e-05 -0.05375" quat="0.707081 -0.00599604 -0.00599604 0.707081" mass="0.385" diaginertia="0.001743 0.00151729 0.000514712" />
                        <joint name="Left_Hip_Roll" pos="0 0 0" axis="1 0 0" limited="true" range="-0.52 1.57" />
                        <geom type="mesh" contype="0" conaffinity="0" group="1" rgba="0.4 0.4 0.4 0.3" mesh="Hip_Roll_Left" />
                        <geom size="0.05 0.08" pos="0 0 -0.08" type="cylinder" rgba="0.4 0.4 0.4 0.3" />
                        <body name="Hip_Yaw_Left" pos="0 0 -0.081854">
                            <inertial pos="-0.007233 0.000206 -0.089184" quat="0.696808 -0.033953 -0.0315708 0.715758" mass="2.166" diaginertia="0.0257334 0.0253024 0.00259215" />
                            <joint name="Left_Hip_Yaw" pos="0 0 0" axis="0 0 1" limited="true" range="-1 1" />
                            <geom type="mesh" contype="0" conaffinity="0" group="1" rgba="0.4 0.4 0.4 0.3" mesh="Hip_Yaw_Left" />
                            <geom size="0.05 0.04" pos="-0.015 0 -0.135" quat="0.707141 0.707073 0 0" type="cylinder" rgba="0.4 0.4 0.4 0.3" />
                            <body name="Shank_Left" pos="-0.014 0 -0.134">
                                <inertial pos="-0.006012 0.000259 -0.124318" quat="0.997573 0.00144024 -0.023949 0.0653706" mass="1.73" diaginertia="0.0346951 0.0345375 0.00185844" />
                                <joint name="Left_Knee_Pitch" pos="0 0 0" axis="0 1 0" limited="true" range="0 2.34" />
                                <geom type="mesh" contype="0" conaffinity="0" group="1" rgba="0.4 0.4 0.4 0.3" mesh="Shank_Left" />
                                <geom size="0.05 0.04 0.05" pos="0 0 -0.13" type="box" rgba="0.4 0.4 0.4 0.3" />
                                <body name="Ankle_Cross_Left" pos="0 0 -0.28">
                                    <inertial pos="-0.003722 0 -0.007981" quat="0.443136 0.551027 0.551027 0.443136" mass="0.073" diaginertia="2.9e-05 2.56589e-05 1.13411e-05" />
                                    <joint name="Left_Ankle_Pitch" pos="0 0 0" axis="0 1 0" limited="true" range="-0.87 0.35" />
                                    <geom type="mesh" contype="0" conaffinity="0" group="1" rgba="0.4 0.4 0.4 0.3" mesh="Ankle_Cross_Left" />
                                    <body name="left_foot_link" pos="0 0.00025 -0.012">
                                        <inertial pos="-0.000249 0 -0.00914" quat="0 0.679927 0 0.733279" mass="0.685" diaginertia="0.00268212 0.002385 0.000726885" />
                                        <joint name="Left_Ankle_Roll" pos="0 0 0" axis="1 0 0" limited="true" range="-0.44 0.44" />
                                        <geom type="mesh" contype="0" conaffinity="0" group="1" rgba="0.4 0.4 0.4 0.3" mesh="left_foot_link" />
                                        <geom size="0.1115 0.05 0.015" pos="0.01 0 -0.015" type="box" rgba="0.4 0.4 0.4 0.3" />
                                    </body>
                                </body>
                            </body>
                        </body>
                    </body>
                </body>
                <body name="Hip_Pitch_Right" pos="0 -0.106 0">
                    <inertial pos="0.000534 0.007514 -0.018082" quat="0.973446 -0.228403 0.0147148 -0.00419349" mass="1.021" diaginertia="0.00180552 0.0014632 0.00124928" />
                    <joint name="Right_Hip_Pitch" pos="0 0 0" axis="0 1 0" limited="true" range="-1.8 1.57" />
                    <geom type="mesh" contype="0" conaffinity="0" group="1" rgba="0.76 0.76 0.76 0.2" mesh="Hip_Pitch_Right" />
                    <body name="Hip_Roll_Right" pos="0 0 -0.02">
                        <inertial pos="0.001099 2.4e-05 -0.053748" quat="0.707081 -0.00599604 -0.00599604 0.707081" mass="0.385" diaginertia="0.001743 0.00151729 0.000514712" />
                        <joint name="Right_Hip_Roll" pos="0 0 0" axis="1 0 0" limited="true" range="-1.57 0.52" />
                        <geom type="mesh" contype="0" conaffinity="0" group="1" rgba="0.4 0.4 0.4 0.3" mesh="Hip_Roll_Right" />
                        <geom size="0.05 0.08" pos="0 0 -0.08" type="cylinder" rgba="0.4 0.4 0.4 0.3" />
                        <body name="Hip_Yaw_Right" pos="0 0 -0.081854">
                            <inertial pos="-0.007191 -0.000149 -0.08922" quat="0.714468 -0.0315638 -0.0336391 0.698146" mass="2.17" diaginertia="0.0257623 0.0253298 0.00259389" />
                            <joint name="Right_Hip_Yaw" pos="0 0 0" axis="0 0 1" limited="true" range="-1 1" />
                            <geom type="mesh" contype="0" conaffinity="0" group="1" rgba="0.4 0.4 0.4 0.3" mesh="Hip_Yaw_Right" />
                            <geom size="0.05 0.04" pos="-0.015 0 -0.135" quat="0.707141 0.707073 0 0" type="cylinder" rgba="0.4 0.4 0.4 0.3" />
                            <body name="Shank_Right" pos="-0.014 0 -0.134">
                                <inertial pos="-0.005741 -0.000541 -0.122602" quat="0.99926 -0.000580963 -0.023461 -0.0304754" mass="1.79" diaginertia="0.0351717 0.0349574 0.00196589" />
                                <joint name="Right_Knee_Pitch" pos="0 0 0" axis="0 1 0" limited="true" range="0 2.34" />
                                <geom type="mesh" contype="0" conaffinity="0" group="1" rgba="0.4 0.4 0.4 0.3" mesh="Shank_Right" />
                                <geom size="0.05 0.04 0.05" pos="0 0 -0.13" type="box" rgba="0.4 0.4 0.4 0.3" />
                                <body name="Ankle_Cross_Right" pos="0 0 -0.28">
                                    <inertial pos="-0.003722 0 -0.007981" quat="0.443136 0.551027 0.551027 0.443136" mass="0.073" diaginertia="2.9e-05 2.56589e-05 1.13411e-05" />
                                    <joint name="Right_Ankle_Pitch" pos="0 0 0" axis="0 1 0" limited="true" range="-0.87 0.35" />
                                    <geom type="mesh" contype="0" conaffinity="0" group="1" rgba="0.4 0.4 0.4 0.3" mesh="Ankle_Cross_Right" />
                                    <body name="right_foot_link" pos="0 -0.00025 -0.012">
                                        <inertial pos="-0.000248 0 -0.00914" quat="0 0.679927 0 0.733279" mass="0.685" diaginertia="0.00268212 0.002385 0.000726885" />
                                        <joint name="Right_Ankle_Roll" pos="0 0 0" axis="1 0 0" limited="true" range="-0.44 0.44" />
                                        <geom type="mesh" contype="0" conaffinity="0" group="1" rgba="0.4 0.4 0.4 0.3" mesh="right_foot_link" />
                                        <geom size="0.1115 0.05 0.015" pos="0.01 0 -0.015" type="box" rgba="0.4 0.4 0.4 0.3" />
                                    </body>
                                </body>
                            </body>
                        </body>
                    </body>
                </body>
            </body>
        </body>
    </worldbody>
    <actuator>
        <motor name="Left_Shoulder_Pitch" joint="Left_Shoulder_Pitch" ctrlrange="-30.0 30.0" ctrllimited="true" />
        <motor name="Left_Shoulder_Roll" joint="Left_Shoulder_Roll" ctrlrange="-30.0 30.0" ctrllimited="true" />
        <motor name="Left_Elbow_Pitch" joint="Left_Elbow_Pitch" ctrlrange="-30.0 30.0" ctrllimited="true" />
        <motor name="Left_Elbow_Yaw" joint="Left_Elbow_Yaw" ctrlrange="-30.0 30.0" ctrllimited="true" />
        <motor name="Right_Shoulder_Pitch" joint="Right_Shoulder_Pitch" ctrlrange="-30.0 30.0" ctrllimited="true" />
        <motor name="Right_Shoulder_Roll" joint="Right_Shoulder_Roll" ctrlrange="-30.0 30.0" ctrllimited="true" />
        <motor name="Right_Elbow_Pitch" joint="Right_Elbow_Pitch" ctrlrange="-30.0 30.0" ctrllimited="true" />
        <motor name="Right_Elbow_Yaw" joint="Right_Elbow_Yaw" ctrlrange="-30.0 30.0" ctrllimited="true" />
        <motor name="Waist" joint="Waist" ctrlrange="-30.0 30.0" ctrllimited="true" />
        <motor name="Left_Hip_Pitch" joint="Left_Hip_Pitch" ctrlrange="-45.0 45.0" ctrllimited="true" />
        <motor name="Left_Hip_Roll" joint="Left_Hip_Roll" ctrlrange="-45.0 45.0" ctrllimited="true" />
        <motor name="Left_Hip_Yaw" joint="Left_Hip_Yaw" ctrlrange="-30.0 30.0" ctrllimited="true" />
        <motor name="Left_Knee_Pitch" joint="Left_Knee_Pitch" ctrlrange="-65.0 65.0" ctrllimited="true" />
        <motor name="Left_Ankle_Pitch" joint="Left_Ankle_Pitch" ctrlrange="-24.0 24.0" ctrllimited="true" />
        <motor name="Left_Ankle_Roll" joint="Left_Ankle_Roll" ctrlrange="-6.0 6.0" ctrllimited="true" />
        <motor name="Right_Hip_Pitch" joint="Right_Hip_Pitch" ctrlrange="-45.0 45.0" ctrllimited="true" />
        <motor name="Right_Hip_Roll" joint="Right_Hip_Roll" ctrlrange="-45.0 45.0" ctrllimited="true" />
        <motor name="Right_Hip_Yaw" joint="Right_Hip_Yaw" ctrlrange="-30.0 30.0" ctrllimited="true" />
        <motor name="Right_Knee_Pitch" joint="Right_Knee_Pitch" ctrlrange="-65.0 65.0" ctrllimited="true" />
        <motor name="Right_Ankle_Pitch" joint="Right_Ankle_Pitch" ctrlrange="-24.0 24.0" ctrllimited="true" />
        <motor name="Right_Ankle_Roll" joint="Right_Ankle_Roll" ctrlrange="-6.0 6.0" ctrllimited="true" />
    </actuator>
    <sensor>
        <framequat name="orientation" objtype="site" noise="0.001" objname="imu" />
        <gyro name="angular-velocity" site="imu" noise="0.005" />
    </sensor>
</mujoco>
